2020-03-04 16:04:16,922 (38205/MainThread) pgcli.main INFO - No default pager found in environment. Using os default pager
2020-03-04 16:04:16,923 (38205/MainThread) pgcli.main WARNING - import keyring failed: ModuleNotFoundError("No module named 'keyring'").
2020-03-04 16:05:17,348 (38672/MainThread) pgcli.main INFO - No default pager found in environment. Using os default pager
2020-03-04 16:05:17,349 (38672/MainThread) pgcli.main WARNING - import keyring failed: ModuleNotFoundError("No module named 'keyring'").
2020-03-04 16:07:34,063 (38672/MainThread) pgcli.pgexecute ERROR - sql: 'LIMIT 10', error: SyntaxError('syntax error at or near "LIMIT"\nLINE 1: LIMIT 10\n        ^\n')
2020-03-04 16:07:34,067 (38672/MainThread) pgcli.pgexecute ERROR - traceback: 'Traceback (most recent call last):\n  File "/usr/local/Cellar/pgcli/2.2.0_1/libexec/lib/python3.8/site-packages/pgcli/pgexecute.py", line 413, in run\n    yield self.execute_normal_sql(sql) + (sql, True, False)\n  File "/usr/local/Cellar/pgcli/2.2.0_1/libexec/lib/python3.8/site-packages/pgcli/pgexecute.py", line 448, in execute_normal_sql\n    cur.execute(split_sql)\npsycopg2.errors.SyntaxError: syntax error at or near "LIMIT"\nLINE 1: LIMIT 10\n        ^\n\n'
2020-03-04 16:21:16,735 (38672/MainThread) pgcli.pgexecute ERROR - sql: 'LIMIT 10', error: SyntaxError('syntax error at or near "LIMIT"\nLINE 1: LIMIT 10\n        ^\n')
2020-03-04 16:21:16,737 (38672/MainThread) pgcli.pgexecute ERROR - traceback: 'Traceback (most recent call last):\n  File "/usr/local/Cellar/pgcli/2.2.0_1/libexec/lib/python3.8/site-packages/pgcli/pgexecute.py", line 413, in run\n    yield self.execute_normal_sql(sql) + (sql, True, False)\n  File "/usr/local/Cellar/pgcli/2.2.0_1/libexec/lib/python3.8/site-packages/pgcli/pgexecute.py", line 448, in execute_normal_sql\n    cur.execute(split_sql)\npsycopg2.errors.SyntaxError: syntax error at or near "LIMIT"\nLINE 1: LIMIT 10\n        ^\n\n'
2020-03-04 16:21:47,412 (38672/MainThread) pgcli.pgexecute ERROR - sql: "SELECT mp.mpan, mp.profile_class, mp.measurement_class, mp.ssc, eacs.consumption, reg.tpr_id\nFROM properties_electricitymeterreadingevent as rd_ev\nJOIN properties_electricitymeterreading as rd\nON rd.id = rd_ev.reading_id\nJOIN properties_electricitymeterregister as reg\nON reg.id = rd.register_id\nJOIN properties_electricitymeter as met\nON met.id = reg.meter_id\nJOIN properties_electricitymeterpoint as mp\nON mp.id = met.meter_point_id\nLEFT JOIN LATERAL (\n    SELECT consumption, effective_from\n    FROM properties_estimatedannualconsumption\n    WHERE meter_point_id=mp.id\n    ORDER BY effective_from DESC\n    LIMIT 1\n) eacs ON TRUE\nWHERE rd_ev.event_type='READING_FROM_DATA_COLLECTOR_FLOW'\nAND rd_ev.created_at>='2020-01-01'\nAND rd_ev.params->>'bsc_validation_status::native'='failed'", error: QueryCanceled('canceling statement due to user request\n')
2020-03-04 16:21:47,413 (38672/MainThread) pgcli.pgexecute ERROR - traceback: 'Traceback (most recent call last):\n  File "/usr/local/Cellar/pgcli/2.2.0_1/libexec/lib/python3.8/site-packages/pgcli/pgexecute.py", line 413, in run\n    yield self.execute_normal_sql(sql) + (sql, True, False)\n  File "/usr/local/Cellar/pgcli/2.2.0_1/libexec/lib/python3.8/site-packages/pgcli/pgexecute.py", line 448, in execute_normal_sql\n    cur.execute(split_sql)\npsycopg2.errors.QueryCanceled: canceling statement due to user request\n\n'
2020-03-04 16:24:25,879 (38672/MainThread) pgcli.pgexecute ERROR - sql: "SELECT mp.mpan, mp.profile_class, mp.measurement_class, mp.ssc, eacs.consumption as mp_eac, reg.tpr_id\nFROM properties_electricitymeterreadingevent as rd_ev\nJOIN properties_electricitymeterreading as rd\nON rd.id = rd_ev.reading_id\nJOIN properties_electricitymeterregister as reg\nON reg.id = rd.register_id\nJOIN properties_electricitymeter as met\nON met.id = reg.meter_id\nJOIN properties_electricitymeterpoint as mp\nON mp.id = met.meter_point_id\nLEFT JOIN LATERAL (\n    SELECT consumption, effective_from\n    FROM properties_estimatedannualconsumption\n    WHERE meter_point_id=mp.id\n    ORDER BY effective_from DESC\n    LIMIT 1\n) eacs ON TRUE\nWHERE rd_ev.event_type='READING_FROM_DATA_COLLECTOR_FLOW'\nAND rd_ev.created_at>='2020-01-01'\nAND rd_ev.params->>'bsc_validation_status::native'='failed'", error: QueryCanceled('canceling statement due to user request\n')
2020-03-04 16:24:25,882 (38672/MainThread) pgcli.pgexecute ERROR - traceback: 'Traceback (most recent call last):\n  File "/usr/local/Cellar/pgcli/2.2.0_1/libexec/lib/python3.8/site-packages/pgcli/pgexecute.py", line 413, in run\n    yield self.execute_normal_sql(sql) + (sql, True, False)\n  File "/usr/local/Cellar/pgcli/2.2.0_1/libexec/lib/python3.8/site-packages/pgcli/pgexecute.py", line 448, in execute_normal_sql\n    cur.execute(split_sql)\npsycopg2.errors.QueryCanceled: canceling statement due to user request\n\n'
2020-03-04 16:25:24,908 (38672/MainThread) pgcli.pgexecute ERROR - sql: "SELECT mp.mpan, mp.profile_class, mp.measurement_class, mp.ssc, eacs.consumption as eac, eacs.tpr_id, reg.tpr_id\nFROM properties_electricitymeterreadingevent as rd_ev\nJOIN properties_electricitymeterreading as rd\nON rd.id = rd_ev.reading_id\nJOIN properties_electricitymeterregister as reg\nON reg.id = rd.register_id\nJOIN properties_electricitymeter as met\nON met.id = reg.meter_id\nJOIN properties_electricitymeterpoint as mp\nON mp.id = met.meter_point_id\nLEFT JOIN LATERAL (\n    SELECT consumption, effective_from\n    FROM properties_estimatedannualconsumption\n    WHERE meter_point_id=mp.id\n    ORDER BY effective_from DESC\n    LIMIT 1\n) eacs ON TRUE\nWHERE rd_ev.event_type='READING_FROM_DATA_COLLECTOR_FLOW'\nAND rd_ev.created_at>='2020-01-01'\nAND rd_ev.params->>'bsc_validation_status::native'='failed' LIMIT 10", error: UndefinedColumn('column eacs.tpr_id does not exist\nLINE 1: ...asurement_class, mp.ssc, eacs.consumption as eac, eacs.tpr_i...\n                                                             ^\n')
2020-03-04 16:25:24,909 (38672/MainThread) pgcli.pgexecute ERROR - traceback: 'Traceback (most recent call last):\n  File "/usr/local/Cellar/pgcli/2.2.0_1/libexec/lib/python3.8/site-packages/pgcli/pgexecute.py", line 413, in run\n    yield self.execute_normal_sql(sql) + (sql, True, False)\n  File "/usr/local/Cellar/pgcli/2.2.0_1/libexec/lib/python3.8/site-packages/pgcli/pgexecute.py", line 448, in execute_normal_sql\n    cur.execute(split_sql)\npsycopg2.errors.UndefinedColumn: column eacs.tpr_id does not exist\nLINE 1: ...asurement_class, mp.ssc, eacs.consumption as eac, eacs.tpr_i...\n                                                             ^\n\n'
2020-03-04 16:26:11,582 (38672/MainThread) pgcli.pgexecute ERROR - sql: "SELECT mp.mpan, mp.profile_class, mp.measurement_class, mp.ssc, eacs.consumption as eac, eacs.time_pattern_regime, reg.tpr_id\nFROM properties_electricitymeterreadingevent as rd_ev\nJOIN properties_electricitymeterreading as rd\nON rd.id = rd_ev.reading_id\nJOIN properties_electricitymeterregister as reg\nON reg.id = rd.register_id\nJOIN properties_electricitymeter as met\nON met.id = reg.meter_id\nJOIN properties_electricitymeterpoint as mp\nON mp.id = met.meter_point_id\nLEFT JOIN LATERAL (\n    SELECT consumption, effective_from\n    FROM properties_estimatedannualconsumption\n    WHERE meter_point_id=mp.id\n    ORDER BY effective_from DESC\n    LIMIT 1\n) eacs ON TRUE\nWHERE rd_ev.event_type='READING_FROM_DATA_COLLECTOR_FLOW'\nAND rd_ev.created_at>='2020-01-01'\nAND rd_ev.params->>'bsc_validation_status::native'='failed' LIMIT 10", error: UndefinedColumn('column eacs.time_pattern_regime does not exist\nLINE 1: ...asurement_class, mp.ssc, eacs.consumption as eac, eacs.time_...\n                                                             ^\n')
2020-03-04 16:26:11,583 (38672/MainThread) pgcli.pgexecute ERROR - traceback: 'Traceback (most recent call last):\n  File "/usr/local/Cellar/pgcli/2.2.0_1/libexec/lib/python3.8/site-packages/pgcli/pgexecute.py", line 413, in run\n    yield self.execute_normal_sql(sql) + (sql, True, False)\n  File "/usr/local/Cellar/pgcli/2.2.0_1/libexec/lib/python3.8/site-packages/pgcli/pgexecute.py", line 448, in execute_normal_sql\n    cur.execute(split_sql)\npsycopg2.errors.UndefinedColumn: column eacs.time_pattern_regime does not exist\nLINE 1: ...asurement_class, mp.ssc, eacs.consumption as eac, eacs.time_...\n                                                             ^\n\n'
2020-03-04 17:48:43,816 (38672/MainThread) pgcli.pgexecute ERROR - sql: "SELECT mp.mpan, mp.profile_class, mp.measurement_class, mp.ssc, eacs.consumption as eac, eacs.time_pattern_regime, reg.tpr_id\nFROM properties_electricitymeterreadingevent as rd_ev\nJOIN properties_electricitymeterreading as rd\nON rd.id = rd_ev.reading_id\nJOIN properties_electricitymeterregister as reg\nON reg.id = rd.register_id\nJOIN properties_electricitymeter as met\nON met.id = reg.meter_id\nJOIN properties_electricitymeterpoint as mp\nON mp.id = met.meter_point_id\nLEFT JOIN LATERAL (\n    SELECT consumption, time_pattern_regime\n    FROM properties_estimatedannualconsumption\n    WHERE meter_point_id=mp.id AND time_pattern_regime=reg.tpr_id\n    ORDER BY effective_from DESC\n    LIMIT 1\n) eacs ON TRUE\nWHERE rd_ev.event_type='READING_FROM_DATA_COLLECTOR_FLOW'\nAND rd_ev.created_at>='2020-01-01'\nAND rd_ev.params->>'bsc_validation_status::native'='failed' ORDER BY mp.mpan LIMIT 10", error: OperationalError('server closed the connection unexpectedly\n\tThis probably means the server terminated abnormally\n\tbefore or while processing the request.\n')
2020-03-04 17:48:43,818 (38672/MainThread) pgcli.pgexecute ERROR - traceback: 'Traceback (most recent call last):\n  File "/usr/local/Cellar/pgcli/2.2.0_1/libexec/lib/python3.8/site-packages/pgcli/pgexecute.py", line 413, in run\n    yield self.execute_normal_sql(sql) + (sql, True, False)\n  File "/usr/local/Cellar/pgcli/2.2.0_1/libexec/lib/python3.8/site-packages/pgcli/pgexecute.py", line 448, in execute_normal_sql\n    cur.execute(split_sql)\n  File "/usr/local/Cellar/pgcli/2.2.0_1/libexec/lib/python3.8/site-packages/pgcli/pgexecute.py", line 40, in _wait_select\n    state = conn.poll()\npsycopg2.OperationalError: server closed the connection unexpectedly\n\tThis probably means the server terminated abnormally\n\tbefore or while processing the request.\n\n'
2020-03-04 17:48:43,818 (38672/MainThread) pgcli.main ERROR - sql: "SELECT mp.mpan, mp.profile_class, mp.measurement_class, mp.ssc, eacs.consumption as eac, eacs.time_pattern_regime, reg.tpr_id\nFROM properties_electricitymeterreadingevent as rd_ev\nJOIN properties_electricitymeterreading as rd\nON rd.id = rd_ev.reading_id\nJOIN properties_electricitymeterregister as reg\nON reg.id = rd.register_id\nJOIN properties_electricitymeter as met\nON met.id = reg.meter_id\nJOIN properties_electricitymeterpoint as mp\nON mp.id = met.meter_point_id\nLEFT JOIN LATERAL (\n    SELECT consumption, time_pattern_regime\n    FROM properties_estimatedannualconsumption\n    WHERE meter_point_id=mp.id AND time_pattern_regime=reg.tpr_id\n    ORDER BY effective_from DESC\n    LIMIT 1\n) eacs ON TRUE\nWHERE rd_ev.event_type='READING_FROM_DATA_COLLECTOR_FLOW'\nAND rd_ev.created_at>='2020-01-01'\nAND rd_ev.params->>'bsc_validation_status::native'='failed' ORDER BY mp.mpan LIMIT 10;", error: OperationalError('server closed the connection unexpectedly\n\tThis probably means the server terminated abnormally\n\tbefore or while processing the request.\n')
2020-03-04 17:48:43,822 (38672/MainThread) pgcli.main ERROR - traceback: 'Traceback (most recent call last):\n  File "/usr/local/Cellar/pgcli/2.2.0_1/libexec/lib/python3.8/site-packages/pgcli/main.py", line 638, in execute_command\n    output, query = self._evaluate_command(text)\n  File "/usr/local/Cellar/pgcli/2.2.0_1/libexec/lib/python3.8/site-packages/pgcli/main.py", line 883, in _evaluate_command\n    for title, cur, headers, status, sql, success, is_special in res:\n  File "/usr/local/Cellar/pgcli/2.2.0_1/libexec/lib/python3.8/site-packages/pgcli/pgexecute.py", line 413, in run\n    yield self.execute_normal_sql(sql) + (sql, True, False)\n  File "/usr/local/Cellar/pgcli/2.2.0_1/libexec/lib/python3.8/site-packages/pgcli/pgexecute.py", line 448, in execute_normal_sql\n    cur.execute(split_sql)\n  File "/usr/local/Cellar/pgcli/2.2.0_1/libexec/lib/python3.8/site-packages/pgcli/pgexecute.py", line 40, in _wait_select\n    state = conn.poll()\npsycopg2.OperationalError: server closed the connection unexpectedly\n\tThis probably means the server terminated abnormally\n\tbefore or while processing the request.\n\n'
